<?xml version="1.0"?>
<robot xmlns:xacro="http://www.ros.org/wiki/xacro" name="test">

   <link name="world"/>


    <link name="base_link">
        <inertial>
            <origin xyz="0.0 0.0 0.0" rpy="0.0 0.0 0.0"/>
            <mass value="0.0"/>
            <inertia ixx="0.0" ixy="0.0" ixz="0.0" iyy="0.0" iyz="0.0" izz="0.0"/>
        </inertial>
        <visual name="">
            <origin xyz="0.0 0 0.0" rpy="0.0 0.0 0.0"/>
            <geometry>
                <mesh filename="package://gimbal_urdf/meshes/base_link2.STL" scale="10 10 10"/>
            </geometry>
            <material name="">
                <color rgba="0.757 0.969 0.98 1"/>
                <texture filename=""/>
            </material>
        </visual>
        <collision>
            <origin xyz="0.0 0.0 0.0" rpy="0.0 0.0 0.0"/>
            <geometry>
                <mesh filename="package://gimbal_urdf/meshes/base_link2.STL" scale="10 10 10"/>
            </geometry>
        </collision>
    </link>

    <joint name="base_joint" type="fixed">
        <origin xyz="0.0 0.0 0.3" rpy="-0 0 -0.0"/>
        <parent link="world"/>
        <child link="base_link"/>
        <calibration rising="0.0"/>
        <dynamics damping="0.0" friction="0.0"/>
        <limit lower="-3.14" upper="3.14" effort="30" velocity="1.0"/>
        
    </joint>



    <link name="1st_link">
        <inertial>
            <origin xyz="0.0 0.0 0.0" rpy="0.0 0.0 0.0"/>
            <mass value="0.0"/>
            <inertia ixx="0.0" ixy="0.0" ixz="0.0" iyy="0.0" iyz="0.0" izz="0.0"/>
        </inertial>
        <visual name="">
            <origin xyz="0 0 0.0 " rpy="0.0 0.0 0.0"/>
            <geometry>
                <mesh filename="package://gimbal_urdf/meshes/1st_link2.STL" scale="10 10 10"/>
            </geometry>
            <material name="">
                <color rgba="0.757 0.969 0.98 1"/>
                <texture filename=""/>
            </material>
        </visual>
        <collision>
            <origin xyz="0.0 0.0 0.0" rpy="0.0 0.0 0.0"/>
            <geometry>
                <mesh filename="package://gimbal_urdf/meshes/1st_link2.STL" scale="10 10 10"/>
            </geometry>
        </collision>
    </link>

    <joint name="1st_to_base" type="revolute">
        <origin xyz="0.253 -0.5045 0.482" rpy="1.57079632 0 -1.57079632"/>
        <parent link="base_link"/>
        <child link="1st_link"/>
        <axis xyz="0.0 1 0.0"/>
        <limit lower="-3.14" upper="3.14" effort="0" velocity="0" />
    </joint>



    <link name="2nd_link">
        <inertial>
            <origin xyz="0.0 0.0 0.0" rpy="0.0 0.0 0.0"/>
            <mass value="0.0"/>
            <inertia ixx="0.0" ixy="0.0" ixz="0.0" iyy="0.0" iyz="0.0" izz="0.0"/>
        </inertial>
        <visual name="">
            <origin xyz="0.0 0.0 0.0" rpy="0.0 0.0 0.0"/>
            <geometry>
                <mesh filename="package://gimbal_urdf/meshes/2nd_link2.STL" scale="10 10 10"/>
            </geometry>
            <material name="">
                <color rgba="0.757 0.969 0.98 1"/>
                <texture filename=""/>
            </material>
        </visual>
        <collision>
            <origin xyz="0.0 0.0 0.0" rpy="0.0 0.0 0.0"/>
            <geometry>
                <mesh filename="package://gimbal_urdf/meshes/2nd_link2.STL" scale="10 10 10"/>
            </geometry>
        </collision>
    </link>
    
    <joint name="2nd_to_1st" type="revolute">
        <origin xyz="-0.283 -0.486 0" rpy="0 0 0"/>
        <parent link="1st_link"/>
        <child link="2nd_link"/>
        <axis xyz="1 0 0"/>
        <limit lower="-3.14" upper="3.14" effort="0" velocity="0" />
    </joint>



    <link name="3rd_link">
        <inertial>
            <origin xyz="0.0 0.0 0.0" rpy="0.0 0.0 0.0"/>
            <mass value="0.0"/>
            <inertia ixx="0.0" ixy="0.0" ixz="0.0" iyy="0.0" iyz="0.0" izz="0.0"/>
        </inertial>
        <visual name="">
            <origin xyz="0.0 0.0 0.0" rpy="0.0 0.0 0.0"/>
            <geometry>
                <mesh filename="package://gimbal_urdf/meshes/3rd_link2.STL" scale="10 10 10"/>
            </geometry>
            <material name="">
                <color rgba="0.757 0.969 0.98 1"/>
                <texture filename=""/>
            </material>
        </visual>
        <collision>
            <origin xyz="0.0 0.0 0.0" rpy="0.0 0.0 0.0"/>
            <geometry>
                <mesh filename="package://gimbal_urdf/meshes/3rd_link2.STL" scale="10 10 10"/>
            </geometry>
        </collision>
    </link>
    
    <joint name="3rd_to_2nd" type="revolute">
        <origin xyz="0.4 0.0035 -0.2915" rpy="0 -1.57079632 0"/>
        <parent link="2nd_link"/>
        <child link="3rd_link"/>
        <axis xyz="1 0 0"/>
        <limit lower="-3.14" upper="3.14" effort="0" velocity="0" />
    </joint>

    <link name="4th_link">
        <inertial>
            <origin xyz="0.0 0.0 0.0" rpy="0.0 1.5707 0.0"/>
            <mass value="0.0"/>
            <inertia ixx="0.0" ixy="0.0" ixz="0.0" iyy="0.0" iyz="0.0" izz="0.0"/>
        </inertial>
        <visual name="">
            <origin xyz="0.0 0.0 0.0" rpy="0.0 1.5707 0.0"/>
            <geometry>
                <cylinder radius="0.1" length="0.05"/>
            </geometry>
            <material name="">
                <color rgba="0 0.969 0.98 1"/>
                <texture filename=""/>
            </material>
        </visual>
        <!-- <collision>
            <origin xyz="5.0 0.0 0.0" rpy="0.0 0.0 0.0"/>
            <geometry>
                <cylinder radius="0.1" length="0.1"/>
            </geometry>
        </collision> -->
    </link>

    <joint name="lens_ee" type="fixed">
        <origin xyz="0.5 0 -0.125" rpy="0 0 0"/>
        <parent link="3rd_link"/>
        <child link="4th_link"/>
    </joint>

</robot>